Workbook

Sheet expert_rules
A1: Template_ID | B1: reaction_smarts | C1: Reaction_source | D1: Reaction_type_O | G1: Reaction_type
A2: 92 | B2: [#6:1][C:2](=O)O[C:5][C:6][OH1]>>[*:1][C:2](=O)O[C:6][C:5]O | C2: SyGMa | D2: glycination_(aliphatic_carboxyl) | E2: =VLOOKUP(B2,Sheet2!A:B,2,0) -> #N/A | F2: =VLOOKUP(B2,[1]Sheet1!$C:$G,5,0) -> acetyl_shift | G2: acetyl_shift
A3: 133 | B3: [*:1][OH1:2]>>[*:1][O:2]C(=O)C | C3: SyGMa | D3: Glutathione _ Conjugated _ (Epoxide) | E3: =VLOOKUP(B3,Sheet2!A:B,2,0) -> acetylation | F3: =VLOOKUP(B3,[1]Sheet1!$C:$G,5,0) -> #N/A | G3: acetylation
A4: 136 | B4: [*;!#6:1][NH2:2]>>[*:1][N:2]C(=O)C | C4: SyGMa | D4: all_dehydro | E4: =VLOOKUP(B4,Sheet2!A:B,2,0) -> acetylation | F4: =VLOOKUP(B4,[1]Sheet1!$C:$G,5,0) -> #N/A | G4: acetylation
A5: 150 | B5: [*;!#6;!#1:1][NH2:2]>>[*:1][N:2]C(=O)C | C5: SyGMa | D5: Secondary alcohol oxidation (benzyl) | E5: =VLOOKUP(B5,Sheet2!A:B,2,0) -> acetylation | F5: =VLOOKUP(B5,[1]Sheet1!$C:$G,5,0) -> #N/A | G5: acetylation
A6: 213 | B6: [c:1][NH2:2]>>[c:1][N:2]C(=O)C | C6: SyGMa | D6: O-glucuronidation_(aliphatic_hydroxyl) | E6: =VLOOKUP(B6,Sheet2!A:B,2,0) -> acetylation | F6: =VLOOKUP(B6,[1]Sheet1!$C:$G,5,0) -> #N/A | G6: acetylation
A7: 238 | B7: [C;!$(C=[*;!#6]):1][NH2:2]>>[C:1][N:2]C(=O)C | C7: SyGMa | D7: carbonyl_reduction_(aliphatic) | E7: =VLOOKUP(B7,Sheet2!A:B,2,0) -> acetylation | F7: =VLOOKUP(B7,[1]Sheet1!$C:$G,5,0) -> #N/A | G7: acetylation
A8: 241 | B8: [C;!$(C=[*;!#6;!#1]):1][NH2:2]>>[C:1][N:2]C(=O)C | C8: SyGMa | D8: all_aliph_hydr | E8: =VLOOKUP(B8,Sheet2!A:B,2,0) -> acetylation | F8: =VLOOKUP(B8,[1]Sheet1!$C:$G,5,0) -> #N/A | G8: acetylation
A9: 281 | B9: [CX4:1][NH1;R:2][CX4:3]>>[C:1][N:2]([C:3])C(=O)C | C9: SyGMa | D9: Ring into a 6-membered NCN ring | E9: =VLOOKUP(B9,Sheet2!A:B,2,0) -> acetylation | F9: =VLOOKUP(B9,[1]Sheet1!$C:$G,5,0) -> #N/A | G9: acetylation
A10: 23 | B10: [#6:3][C:1]#[C:2][#6:4]>>[*:3][C:1]([*:4])[C:2](=O)[O] | C10: GLORY | D10: O-deacetylation | E10: =VLOOKUP(B10,Sheet2!A:B,2,0) -> #N/A | F10: =VLOOKUP(B10,[1]Sheet1!$C:$G,5,0) -> acetylene oxidation, complete oxidation | G10: acetylene oxidation, complete oxidation
A11: 24 | B11: [#6:3][C:1]#[C:2][#6:4]>>[*:3][C:1]([*:4])=[C:2](=O) | C11: GLORY | D11: methylation_(thiol) | E11: =VLOOKUP(B11,Sheet2!A:B,2,0) -> #N/A | F11: =VLOOKUP(B11,[1]Sheet1!$C:$G,5,0) -> acetylene oxidation, first step | G11: acetylene oxidation, first step
A12: 187 | B12: [c:1][CH1:2]=[O:3]>>[c:1][C:2]-[O:3] | C12: SyGMa | D12: sulfide_oxidation_(c-S-C) | E12: =VLOOKUP(B12,Sheet2!A:B,2,0) -> reduction | F12: =VLOOKUP(B12,[1]Sheet1!$C:$G,5,0) -> aldehyde_reduction_(aliphatic) | G12: aldehyde_reduction_(aliphatic)
A13: 188 | B13: [C:1][CH1:2]=[O:3]>>[C:1][C:2]-[O:3] | C13: SyGMa | D13: sulfide_oxidation_(C-S-C) | E13: =VLOOKUP(B13,Sheet2!A:B,2,0) -> reduction | F13: =VLOOKUP(B13,[1]Sheet1!$C:$G,5,0) -> aldehyde_reduction_(aliphatic) | G13: aldehyde_reduction_(aliphatic)
... A75: 9 | B75: [C;H2;$(Cc),$(CCc),$(CC=C),$(C[CH3]),$(C[CH2]):1][*;Br,Cl,I,$(OS(=O)(=O)[O-]),$(OS(=O)(=O)O*),$(OP(=O)(O*)O*)]>>[C;H2:1]SCC(C(=O)NCC(=O)O)NC(=O)CCC(C(=O)O)N | C75: GLORYx | D75: acetyl_shift | E75: =VLOOKUP(B75,Sheet2!A:B,2,0) -> glutahionation | F75: =VLOOKUP(B75,[1]Sheet1!$C:$G,5,0) -> #N/A | G75: glutahionation
A76: 1 | B76: [c:1][*;Br,Cl,I,$(OS(=O)(=O)[O-]),$(OS(=O)(=O)O*),$(OP(=O)(O*)O*)]>>[c:1]SCC(C(=O)NCC(=O)O)NC(=O)CCC(C(=O)O)N | C76: GLORYx | D76: =VLOOKUP(B76,Sheet2!A:B,2,0) -> glutahionation | E76: =VLOOKUP(B76,Sheet2!A:B,2,0) -> glutahionation | F76: =VLOOKUP(B76,[1]Sheet1!$C:$G,5,0) -> glutathione_conjugation_(aromatic_nucleophilic_substitution) | G76: glutathione_conjugation_(aromatic_nucleophilic_substitution)
A77: 3 | B77: [C;$(C=C):1](Cl)>>[C:1](SCC(C(=O)NCC(=O)O)NC(=O)CCC(C(=O)O)N) | C77: GLORYx | D77: aromatic_hydroxylation_(ortho_to_2_substituents) | E77: =VLOOKUP(B77,Sheet2!A:B,2,0) -> glutahionation | F77: =VLOOKUP(B77,[1]Sheet1!$C:$G,5,0) -> glutathione_conjugation_(chloroalkene) | G77: glutathione_conjugation_(chloroalkene)
A78: 8 | B78: [C;$(C(=N[#6])=[S,O]):1]=[N:2]>>[C:1](SCC(C(=O)NCC(=O)O)NC(=O)CCC(C(=O)O)N)[N:2] | C78: GLORYx | D78: haloacid_hydrolysis | E78: =VLOOKUP(B78,Sheet2!A:B,2,0) -> #N/A | F78: =VLOOKUP(B78,[1]Sheet1!$C:$G,5,0) -> glutathione_conjugation_(isocyanate_isothiocyanate) | G78: glutathione_conjugation_(isocyanate_isothiocyanate)
A79: 4 | B79: [C:1]#[N:2]>>[C:1](SCC(C(=O)NCC(=O)O)NC(=O)CCC(C(=O)O)N)=[N:2] | C79: GLORYx | D79: dephosphorylation | E79: =VLOOKUP(B79,Sheet2!A:B,2,0) -> #N/A | F79: =VLOOKUP(B79,[1]Sheet1!$C:$G,5,0) -> glutathione_conjugation_(nitrile) | G79: glutathione_conjugation_(nitrile)
A80: 152 | B80: [*;!#6;!#1;!$(*=O):1][O:2][CH3]>>[*:1][O:2] | C80: SyGMa | D80: benzylic_hydroxylation_(c-CH1-CH3) | E80: =VLOOKUP(B80,Sheet2!A:B,2,0) -> other | F80: =VLOOKUP(B80,[1]Sheet1!$C:$G,5,0) -> het-O-demethylation | G80: het-O-demethylation
A81: 105 | B81: [#6:2]=[N:4]-[N:5]>>([*:2]=O.[N:4]-[N:5]) | C81: SyGMa | D81: nitrile_to_amide | E81: =VLOOKUP(B81,Sheet2!A:B,2,0) -> hydrolysis | F81: =VLOOKUP(B81,[1]Sheet1!$C:$G,5,0) -> hydrazone_hydrolysis | G81: hydrazone_hydrolysis
A82: 22 | B82: [#6:1][O:2][C:3]>>[*:1][O;H1:2].[C;X3:3](=O) | C82: GLORY | D82: Carbon desulfurization | E82: =VLOOKUP(B82,Sheet2!A:B,2,0) -> hydrolysis | F82: =VLOOKUP(B82,[1]Sheet1!$C:$G,5,0) -> #N/A | G82: hydrolysis
A83: 135 | B83: [*:5][*;!#6;!$(S(=O)(=O)N);!$(P(O)(O)(O)=O):1](=[*;!#6:2])[N,O:3][*:4]>>([*:5][*:1](=[*:2])O.[*:3][*:4]) | C83: SyGMa | D83: O-glucuronidation_(aromatic_carboxyl) | E83: =VLOOKUP(B83,Sheet2!A:B,2,0) -> hydrolysis | F83: =VLOOKUP(B83,[1]Sheet1!$C:$G,5,0) -> #N/A | G83: hydrolysis
A84: 156 | B84: [C$(C[#6!H3]):2](=[O:3])[N:4][*;!#6:5]>>([C:2](=[O:3])O.[N:4][*:5]) | C84: SyGMa | D84: benzylic_hydroxylation_(c-CH2-CR) | E84: =VLOOKUP(B84,Sheet2!A:B,2,0) -> hydrolysis | F84: =VLOOKUP(B84,[1]Sheet1!$C:$G,5,0) -> #N/A | G84: hydrolysis
A85: 97 | B85: [#6:1][N:2][CH1]([OH1])[*:3]>>([*:1][N:2].C(=O)[*:3]) | C85: SyGMa | D85: hydrolysis_(heteroatom_bonded_amide) | E85: =VLOOKUP(B85,Sheet2!A:B,2,0) -> hydrolysis | F85: =VLOOKUP(B85,[1]Sheet1!$C:$G,5,0) -> hydrolysis_(CNC(OH)R) | G85: hydrolysis_(CNC(OH)R)
A86: 112 | B86: [#6:1][N:2][CH1]([OH1])[*;!#1:3]>>([#6:1][N:2].C(=O)[*:3]) | C86: SyGMa | D86: Olefin oxidation | E86: =VLOOKUP(B86,Sheet2!A:B,2,0) -> hydrolysis | F86: =VLOOKUP(B86,[1]Sheet1!$C:$G,5,0) -> hydrolysis_(CNC(OH)R) | G86: hydrolysis_(CNC(OH)R)
A87: 161 | B87: [C$(C[#6!H3]):2](=[O:3])O[#6!H3:4]>>([C:2](=[O:3])O.O[*:4]) | C87: SyGMa | D87: carboxylation_(benzylic_CH3) | E87: =VLOOKUP(B87,Sheet2!A:B,2,0) -> hydrolysis | F87: =VLOOKUP(B87,[1]Sheet1!$C:$G,5,0) -> hydrolysis_(ester) | G87: hydrolysis_(ester)
A88: 167 | B88: [C$(C[#6!H3]):2](=[O:3])O[#6!H3:4]>>([C:2](=[O:3])O.O[#6:4]) | C88: SyGMa | D88: aromatic_N_sulfation2 | E88: =VLOOKUP(B88,Sheet2!A:B,2,0) -> hydrolysis | F88: =VLOOKUP(B88,[1]Sheet1!$C:$G,5,0) -> hydrolysis_(ester) | G88: hydrolysis_(ester)
... A348: 344 | B348: [OH1][C:2]@[*:3]~!@[*:4]~!@[*:5][C;!$(CC1OCC(O)C(O)C1O)](=O)-[OH1]>>O1[C:2][*:3]~[*:4]~[*:5]C1=O | C348: SyGMa | D348: sulfoxide_reduction | E348: =VLOOKUP(B348,Sheet2!A:B,2,0) -> #N/A | F348: =VLOOKUP(B348,[1]Sheet1!$C:$G,5,0) -> #N/A | G348: other

Sheet Sheet1
A1: final type | B1: reaction_smarts
B2: [#6:1]!@[N;R;X3:2]([CH2:3])[CH2:4]>>[#6:1][N:2].O[C:3].O[C:4] | C2: dealkylation
A3: acetylation | B3: [#6:1]!@[N;R;X3:2]([CH2:3])[CH2:4]>>[#6:1][N:2].O[C:3].O[C:4]
A4: ring opening | B4: [#6:1]!@[N;R;X3:2]([CH2:3])[CH2:4]>>[#6:1][N:2].O[C:3].O[C:4]
A5: other | B5: [c:1]1([O:7][C:9])[c:2][c:3][c;X3:4]([!C:8])[c:5][c:6]1>>([C:1]1(=[O:7])-[C:2]=[C:3]-[C;X3:4](=O)-[C:5]=[C:6]-1.[!C:8].[C:9]) | C5: deacetylation
B6: [c:1]1([O:7][C:9])[c:2][c:3][c;X3:4]([!C:8])[c:5][c:6]1>>([C:1]1(=[O:7])-[C:2]=[C:3]-[C;X3:4](=O)-[C:5]=[C:6]-1.[!C:8].[C:9])
A7: other | B7: [#6:1][C:2](=O)O[C:5][C:6][OH1]>>[*:1][C:2](=O)O[C:6][C:5]O
A8: acetylation | B8: [#7:1][C:2]>>([#7:1].[C:2]=[O]) | C8: dealkylation
A9: hydrolysis | B9: [#7:1][C:2]>>([#7:1].[C:2]=[O])
B10: [#7:1][C:2]>>([#7:1].[C:2]=[O])
A11: oxidation | B11: [#7:1][C:2]>>([#7:1].[C:2]=[O])
A12: other | B12: [#7:1][C:2]>>([#7:1].[C:2]=[O])
A13: demethylation | B13: [#7:1][C:2]>>([#7:1].[C:2]=[O])
A14: sulfation | B14: [#7:1][C:2]>>([#7:1].[C:2]=[O])
A15: acetylation | B15: [#7:1][C:2]>>[#7:1].[C:2]=[O]
A16: hydrolysis | B16: [#7:1][C:2]>>[#7:1].[C:2]=[O]
A17: dealkylation | B17: [#7:1][C:2]>>[#7:1].[C:2]=[O]
A18: oxidation | B18: [#7:1][C:2]>>[#7:1].[C:2]=[O]
A19: other | B19: [#7:1][C:2]>>[#7:1].[C:2]=[O]
A20: demethylation | B20: [#7:1][C:2]>>[#7:1].[C:2]=[O]
A21: sulfation | B21: [#7:1][C:2]>>[#7:1].[C:2]=[O]
A22: acetylation | B22: [NH0;X3:2]!@[C;X4;H2:4]>>([N:2].O[C:4]) | C22: dealkylation
B23: [NH0;X3:2]!@[C;X4;H2:4]>>([N:2].O[C:4])
A24: acetylation | B24: [*;!c:1][NH1;X3:2]!@[CH2:3][#6:4]>>([*:1][N:2].O[C:3][#6:4]) | C24: dealkylation
B25: [*;!c:1][NH1;X3:2]!@[CH2:3][#6:4]>>([*:1][N:2].O[C:3][#6:4])
A26: acetylation | B26: [*;!c:1][NH1;X3:2]!@[CH2:3][#6:4]>>([*:1][N:2].O[C:3][*:4])
A27: dealkylation | B27: [*;!c:1][NH1;X3:2]!@[CH2:3][#6:4]>>([*:1][N:2].O[C:3][*:4])
A28: other | B28: [CX4;H1,H2:1][Cl,Br,I]>>[C:1]O
B29: [#6:1][CH2:2][CH3:3]>>[*:1][C:2][C:3]O | C29: hydroxylation
B30: [C;X4;!H0;!$(Cc):1]>>[C:1]O | C30: hydroxylation
B31: [C;$(C=*),$(C#*):1][CH3:2]>>[C:1][C:2]O | C31: hydroxylation
B32: [*;!c;$(*=*):1][CH2;R:2][*;!c;$(*=*):3]>>[*:1][C:2](O)[*:3] | C32: hydroxylation
B33: [C:1][CH1;X4:2]([C;!$([CH3]):3])[N,C&$([C]=*):4]>>[C:1][C:2](O)([C:3])[*:4] | C33: hydroxylation
B34: [C:1][NH2:2]>>[C:1][N:2]S(=O)(=O)O | C34: sulfation
B35: [C:1][NH1;R:2][C:3]>>[C:1][N:2]([C:3])S(=O)(=O)O | C35: sulfation
B36: [CX4:1][CH2;R:2][*;!c;$(*=*),$([#7]):3]>>[C:1][C:2](O)[*:3] | C36: hydroxylation
B37: [CH1;$(C(-[#6])(-[#6])-[CH3]):1][CH3:2]>>[C:1][C:2]O | C37: hydroxylation
B38: [CX4:1][CH2:2][CX4:3]>>[C:1][C:2](O)[C:3] | C38: hydroxylation
B39: [CX4;H2:1][CH2;R:2][CX4;H2:3]>>[C:1][C:2](O)[C:3] | C39: hydroxylation
B40: [CX4:1][CH2:2][CH3]>>[C:1][C:2](O)C | C40: hydroxylation
...

Sheet Sheet2
A1: reaction_smarts
A2: [#6:1]!@[N;R;X3:2]([CH2:3])[CH2:4]>>[#6:1][N:2].O[C:3].O[C:4] | B2: dealkylation
A3: [c:1]1([O:7][C:9])[c:2][c:3][c;X3:4]([!C:8])[c:5][c:6]1>>([C:1]1(=[O:7])-[C:2]=[C:3]-[C;X3:4](=O)-[C:5]=[C:6]-1.[!C:8].[C:9]) | B3: deacetylation
A4: [#7:1][C:2]>>([#7:1].[C:2]=[O]) | B4: dealkylation
A5: [NH0;X3:2]!@[C;X4;H2:4]>>([N:2].O[C:4]) | B5: dealkylation
A6: [*;!c:1][NH1;X3:2]!@[CH2:3][#6:4]>>([*:1][N:2].O[C:3][#6:4]) | B6: dealkylation
A7: [#6:1][CH2:2][CH3:3]>>[*:1][C:2][C:3]O | B7: hydroxylation
A8: [C;X4;!H0;!$(Cc):1]>>[C:1]O | B8: hydroxylation
A9: [C;$(C=*),$(C#*):1][CH3:2]>>[C:1][C:2]O | B9: hydroxylation
A10: [*;!c;$(*=*):1][CH2;R:2][*;!c;$(*=*):3]>>[*:1][C:2](O)[*:3] | B10: hydroxylation
A11: [C:1][CH1;X4:2]([C;!$([CH3]):3])[N,C&$([C]=*):4]>>[C:1][C:2](O)([C:3])[*:4] | B11: hydroxylation
A12: [C:1][NH2:2]>>[C:1][N:2]S(=O)(=O)O | B12: sulfation
A13: [C:1][NH1;R:2][C:3]>>[C:1][N:2]([C:3])S(=O)(=O)O | B13: sulfation
... A276: [c;$(c1cc2ccccc2n1),$(c1c2ccccc2nc1):1]=,:[c:2]-,:[n:3]>>[C:1](=[O])-[C:2]-[N:3] | B276: oxidation
